2020-02-29 13:35:11,603 ERROR: Exception on /reset_password_request [POST] [in /Users/apple/microblog/venv/lib/python3.7/site-packages/flask/app.py:1891]
Traceback (most recent call last):
  File "/Users/apple/microblog/venv/lib/python3.7/site-packages/flask/app.py", line 2446, in wsgi_app
    response = self.full_dispatch_request()
  File "/Users/apple/microblog/venv/lib/python3.7/site-packages/flask/app.py", line 1951, in full_dispatch_request
    rv = self.handle_user_exception(e)
  File "/Users/apple/microblog/venv/lib/python3.7/site-packages/flask/app.py", line 1820, in handle_user_exception
    reraise(exc_type, exc_value, tb)
  File "/Users/apple/microblog/venv/lib/python3.7/site-packages/flask/_compat.py", line 39, in reraise
    raise value
  File "/Users/apple/microblog/venv/lib/python3.7/site-packages/flask/app.py", line 1949, in full_dispatch_request
    rv = self.dispatch_request()
  File "/Users/apple/microblog/venv/lib/python3.7/site-packages/flask/app.py", line 1935, in dispatch_request
    return self.view_functions[rule.endpoint](**req.view_args)
  File "/Users/apple/microblog/app/routes.py", line 172, in reset_password_request
    send_password_reset_email(user)
  File "/Users/apple/microblog/app/email.py", line 26, in send_password_reset_email
    html_body=None)
  File "/Users/apple/microblog/app/email.py", line 17, in send_email
    mail.send(msg)
  File "/Users/apple/microblog/venv/lib/python3.7/site-packages/flask_mail.py", line 491, in send
    with self.connect() as connection:
  File "/Users/apple/microblog/venv/lib/python3.7/site-packages/flask_mail.py", line 144, in __enter__
    self.host = self.configure_host()
  File "/Users/apple/microblog/venv/lib/python3.7/site-packages/flask_mail.py", line 158, in configure_host
    host = smtplib.SMTP(self.mail.server, self.mail.port)
  File "/Library/Frameworks/Python.framework/Versions/3.7/lib/python3.7/smtplib.py", line 251, in __init__
    (code, msg) = self.connect(host, port)
  File "/Library/Frameworks/Python.framework/Versions/3.7/lib/python3.7/smtplib.py", line 336, in connect
    self.sock = self._get_socket(host, port, self.timeout)
  File "/Library/Frameworks/Python.framework/Versions/3.7/lib/python3.7/smtplib.py", line 307, in _get_socket
    self.source_address)
  File "/Library/Frameworks/Python.framework/Versions/3.7/lib/python3.7/socket.py", line 727, in create_connection
    raise err
  File "/Library/Frameworks/Python.framework/Versions/3.7/lib/python3.7/socket.py", line 716, in create_connection
    sock.connect(sa)
TimeoutError: [Errno 60] Operation timed out
2020-02-29 13:37:35,411 INFO: Microblog startup [in /Users/apple/microblog/app/__init__.py:54]
2020-02-29 13:37:47,652 INFO: Microblog startup [in /Users/apple/microblog/app/__init__.py:54]
2020-02-29 13:37:53,517 INFO: Microblog startup [in /Users/apple/microblog/app/__init__.py:54]
2020-02-29 13:40:04,813 INFO: Microblog startup [in /Users/apple/microblog/app/__init__.py:54]
2020-02-29 13:43:02,631 INFO: Microblog startup [in /Users/apple/microblog/app/__init__.py:54]
2020-02-29 13:45:07,502 INFO: Microblog startup [in /Users/apple/microblog/app/__init__.py:54]
2020-02-29 13:45:22,435 ERROR: Exception on /reset_password_request [POST] [in /Users/apple/microblog/venv/lib/python3.7/site-packages/flask/app.py:1891]
Traceback (most recent call last):
  File "/Users/apple/microblog/venv/lib/python3.7/site-packages/flask/app.py", line 2446, in wsgi_app
    response = self.full_dispatch_request()
  File "/Users/apple/microblog/venv/lib/python3.7/site-packages/flask/app.py", line 1951, in full_dispatch_request
    rv = self.handle_user_exception(e)
  File "/Users/apple/microblog/venv/lib/python3.7/site-packages/flask/app.py", line 1820, in handle_user_exception
    reraise(exc_type, exc_value, tb)
  File "/Users/apple/microblog/venv/lib/python3.7/site-packages/flask/_compat.py", line 39, in reraise
    raise value
  File "/Users/apple/microblog/venv/lib/python3.7/site-packages/flask/app.py", line 1949, in full_dispatch_request
    rv = self.dispatch_request()
  File "/Users/apple/microblog/venv/lib/python3.7/site-packages/flask/app.py", line 1935, in dispatch_request
    return self.view_functions[rule.endpoint](**req.view_args)
  File "/Users/apple/microblog/app/routes.py", line 172, in reset_password_request
    send_password_reset_email(user)
  File "/Users/apple/microblog/app/email.py", line 27, in send_password_reset_email
    user=user, token=token))
  File "/Users/apple/microblog/venv/lib/python3.7/site-packages/flask/templating.py", line 138, in render_template
    ctx.app.jinja_env.get_or_select_template(template_name_or_list),
  File "/Users/apple/microblog/venv/lib/python3.7/site-packages/jinja2/environment.py", line 930, in get_or_select_template
    return self.get_template(template_name_or_list, parent, globals)
  File "/Users/apple/microblog/venv/lib/python3.7/site-packages/jinja2/environment.py", line 883, in get_template
    return self._load_template(name, self.make_globals(globals))
  File "/Users/apple/microblog/venv/lib/python3.7/site-packages/jinja2/environment.py", line 857, in _load_template
    template = self.loader.load(self, name, globals)
  File "/Users/apple/microblog/venv/lib/python3.7/site-packages/jinja2/loaders.py", line 117, in load
    source, filename, uptodate = self.get_source(environment, name)
  File "/Users/apple/microblog/venv/lib/python3.7/site-packages/flask/templating.py", line 60, in get_source
    return self._get_source_fast(environment, template)
  File "/Users/apple/microblog/venv/lib/python3.7/site-packages/flask/templating.py", line 89, in _get_source_fast
    raise TemplateNotFound(template)
jinja2.exceptions.TemplateNotFound: email/reset_password.html
2020-02-29 13:47:51,387 INFO: Microblog startup [in /Users/apple/microblog/app/__init__.py:54]
2020-02-29 13:49:54,822 INFO: Microblog startup [in /Users/apple/microblog/app/__init__.py:54]
2020-02-29 13:50:06,535 ERROR: Exception on /reset_password_request [POST] [in /Users/apple/microblog/venv/lib/python3.7/site-packages/flask/app.py:1891]
Traceback (most recent call last):
  File "/Users/apple/microblog/venv/lib/python3.7/site-packages/flask/app.py", line 2446, in wsgi_app
    response = self.full_dispatch_request()
  File "/Users/apple/microblog/venv/lib/python3.7/site-packages/flask/app.py", line 1951, in full_dispatch_request
    rv = self.handle_user_exception(e)
  File "/Users/apple/microblog/venv/lib/python3.7/site-packages/flask/app.py", line 1820, in handle_user_exception
    reraise(exc_type, exc_value, tb)
  File "/Users/apple/microblog/venv/lib/python3.7/site-packages/flask/_compat.py", line 39, in reraise
    raise value
  File "/Users/apple/microblog/venv/lib/python3.7/site-packages/flask/app.py", line 1949, in full_dispatch_request
    rv = self.dispatch_request()
  File "/Users/apple/microblog/venv/lib/python3.7/site-packages/flask/app.py", line 1935, in dispatch_request
    return self.view_functions[rule.endpoint](**req.view_args)
  File "/Users/apple/microblog/app/routes.py", line 172, in reset_password_request
    send_password_reset_email(user)
  File "/Users/apple/microblog/app/email.py", line 34, in send_password_reset_email
    html_body=None)
  File "/Users/apple/microblog/app/email.py", line 17, in send_email
    mail.send(msg)
  File "/Users/apple/microblog/venv/lib/python3.7/site-packages/flask_mail.py", line 491, in send
    with self.connect() as connection:
  File "/Users/apple/microblog/venv/lib/python3.7/site-packages/flask_mail.py", line 144, in __enter__
    self.host = self.configure_host()
  File "/Users/apple/microblog/venv/lib/python3.7/site-packages/flask_mail.py", line 165, in configure_host
    host.login(self.mail.username, self.mail.password)
  File "/Library/Frameworks/Python.framework/Versions/3.7/lib/python3.7/smtplib.py", line 730, in login
    raise last_exception
  File "/Library/Frameworks/Python.framework/Versions/3.7/lib/python3.7/smtplib.py", line 721, in login
    initial_response_ok=initial_response_ok)
  File "/Library/Frameworks/Python.framework/Versions/3.7/lib/python3.7/smtplib.py", line 642, in auth
    raise SMTPAuthenticationError(code, resp)
smtplib.SMTPAuthenticationError: (534, b'5.7.14 <https://accounts.google.com/signin/continue?sarp=1&scc=1&plt=AKgnsbt\n5.7.14 -vkBkkQ292zR9fbAkv8uCrn4U4isCdarhFufXgQLyDNzZffvnM0yNxvLs5Tmfn_HHF5Nf\n5.7.14 HTgGhUPU9_W2bssZC_SiJkEpeUpYDJrTUwhTaAQ-akggq_7KgolFA0sOPggV_YdW>\n5.7.14 Please log in via your web browser and then try again.\n5.7.14  Learn more at\n5.7.14  https://support.google.com/mail/answer/78754 o19sm15315271pjr.2 - gsmtp')
2020-02-29 13:51:30,135 INFO: Microblog startup [in /Users/apple/microblog/app/__init__.py:54]
